Workbook

Sheet README
A1: AutoBrain EV data: Mahindra (4 models) + Tata (7 models)
A2: Updated 22 Oct 2026. Specs verified from brochure (S009). All BaaS prices + One battery-included price verified from Mahindra website (S010, S011). Other battery-included prices still need checking.
A3: DECISION LAYER (new):
A4: Assumptions: editable tariffs, daily km, years (yellow cells). Engine_Variants: one clean row per variant, numeric fields, running cost and 5-year cost formulas, watch-outs.
A5: Variant_Ladder: every price step within a model, with exactly what you gain and which gains are factory-only. Engine_Rules: how the engine/LLM must use the data.
A6: Test_Cases: 6 buyer profiles run through the logic as a sanity check. Range-led ranking puts independently tested range ahead of maker claims.
A10: What each tab is for
A11: Variants: one line per variant (trim + battery + pricing type). Core numbers only.
A12: Features: one line per variant per feature. This is where descriptions go. Never make a new tab per variant.
A13: Sources: one line per receipt. Every value in Variants and Features points to a source_id here.
A14: Open_Questions: conflicts and gaps. When two sources disagree, log both here and leave the main cell blank.
A15: Feature_List: the agreed feature names. Use exactly these names in the Features tab so the data stays comparable.
... A35: Progress
A36: Variants in sheet | B36: =COUNTA(Variants!A2:A200) -> 87
A37: Pending | B37: =COUNTIF(Variants!N2:N200,"pending") -> 2
A38: Verified | B38: =COUNTIF(Variants!N2:N200,"verified") -> 65
A39: Corroborated | B39: =COUNTIF(Variants!N2:N200,"corroborated") -> 20
A40: Conflicting | B40: =COUNTIF(Variants!N2:N200,"conflicting") -> 0
A41: Price mismatches found | B41: =COUNTIF(Variants!R2:R200,"MISMATCH") -> 0

Sheet Assumptions
A1: Assumption | B1: Value | C1: Unit | D1: Why this default / source
A2: Home electricity tariff | B2: 8 | C2: ₹/kWh | D2: Typical Delhi residential slab; change for your city/DISCOM
A3: Public DC fast-charging tariff | B3: 22 | C3: ₹/kWh | D3: Typical Indian public DC rate (Tata Power, Statiq, ChargeZone range ~₹18-25); verify locally
A4: Share of charging done on public DC | B4: 0.1 | C4: fraction | D4: Most private owners charge at home
A5: Daily driving | B5: 40 | C5: km/day | D5: Change to buyer's actual use
A6: Ownership period | B6: 5 | C6: years | D6: Typical first-owner horizon
A7: Annual electricity price increase | B7: 0 | C7: fraction | D7: Kept 0 for simplicity; not yet used in formulas
A9: Edit the yellow cells. Engine_Variants running-cost and 5-year cost columns recalculate from these.
A10: 5-year cost INCLUDES: ex-showroom price + home wall charger (if not included) + electricity.
A11: EXCLUDES: registration, insurance, service, tyres, financing, resale value, discounts. Not a full TCO.

Sheet Engine_Variants
A1: variant_key | B1: sheet_id | C1: brand | D1: model | E1: body_type | F1: variant | G1: pricing_type | H1: price_inr | I1: price_status | J1: battery_kwh | K1: drive | L1: seats | M1: seat_options | N1: range_claimed_km | O1: range_standard | P1: range_maker_realworld_km | Q1: range_tested_km | R1: tested_vs_claim_pct | S1: efficiency_km_per_kwh | T1: efficiency_basis | U1: running_cost_inr_per_km | V1: energy_cost_period_inr | W1: charger_included | X1: charger_cost_inr | Y1: charger_basis | Z1: cost_to_own_period_inr | AA1: boot_l | AB1: ground_clearance_mm | AC1: battery_clearance_mm | AD1: airbags | AE1: esp | AF1: adas | AG1: camera | AH1: sunroof | AI1: ventilated_front | AJ1: adaptive_suspension | AK1: dc_max_kw | AL1: dc_avg_kw_est | AM1: minutes_dc_per_100km | AN1: ac_full_hours_7kw | AO1: onboard_ac_kw | AP1: battery_warranty | AQ1: ncap_status | AR1: ncap_adult_32 | AS1: ncap_child_49 | AT1: terrain_modes | AU1: wading_mm | AV1: watch_outs
A2: MAHINDRA-BE6SPORTEQ-ONE-59 | B2: V001 | C2: Mahindra | D2: BE 6 SPORTEQ | E2: SUV | F2: One 59 kWh | G2: battery included | H2: 1945000 | I2: verified | J2: 59 | K2: RWD | L2: 5 | M2: 5 | N2: 573 | O2: MIDC Part 1 + Part 2 | P2: 400 | S2: 6.78 | T2: Maker real-world claim (estimate) | U2: =IF(S2="","",((1-Assumptions!$B$4)*Assumptions!$B$2+Assumptions!$B$4*Assumptions!$B$3)/S2) -> 1.3864307 | V2: =IF(U2="","",U2*Assumptions!$B$5*365*Assumptions!$B$6) -> 101209.44 | W2: No | X2: 60000 | Y2: 7.2 kW wall box ₹60,000 (Mahindra XEV 9e/9S pages); BE 6 price assumed same | Z2: =IF(OR(G2<>"battery included",H2="",V2=""),"",H2+X2+V2) -> 2106209.4 | AA2: 455 | AB2: 207 | AC2: 222 | AD2: 6 | AE2: Yes | AF2: None | AG2: Rear camera | AH2: None | AI2: No | AJ2: No | AK2: 140 | AL2: 106.2 | AM2: =IF(OR(S2="",AL2=""),"",100/S2/AL2*60) -> 8.3329167 | AN2: 8.7 | AO2: 11 | AP2: Lifetime (1st owner) | AQ2: Rated, coverage unconfirmed | AR2: 31.97 | AS2: 45 | AV2: Crash rating may not cover this version; Wall charger not in price (~₹60,000)
A3: MAHINDRA-BE6SPORTEQ-TWO-59 | B3: V003 | C3: Mahindra | D3: BE 6 SPORTEQ | E3: SUV | F3: Two 59 kWh | G3: battery included | H3: 2095000 | I3: corroborated | J3: 59 | K3: RWD | L3: 5 | M3: 5 | N3: 573 | O3: MIDC Part 1 + Part 2 | P3: 400 | S3: 6.78 | T3: Maker real-world claim (estimate) | U3: =IF(S3="","",((1-Assumptions!$B$4)*Assumptions!$B$2+Assumptions!$B$4*Assumptions!$B$3)/S3) -> 1.3864307 | V3: =IF(U3="","",U3*Assumptions!$B$5*365*Assumptions!$B$6) -> 101209.44 | W3: No | X3: 60000 | Y3: 7.2 kW wall box ₹60,000 (Mahindra XEV 9e/9S pages); BE 6 price assumed same | Z3: =IF(OR(G3<>"battery included",H3="",V3=""),"",H3+X3+V3) -> 2256209.4 | AA3: 455 | AB3: 207 | AC3: 222 | AD3: 6 | AE3: Yes | AF3: None | AG3: 540° | AH3: None | AI3: No | AJ3: No | AK3: 140 | AL3: 106.2 | AM3: =IF(OR(S3="",AL3=""),"",100/S3/AL3*60) -> 8.3329167 | AN3: 8.7 | AO3: 11 | AP3: Lifetime (1st owner) | AQ3: Rated, coverage unconfirmed | AR3: 31.97 | AS3: 45 | AV3: Crash rating may not cover this version; Wall charger not in price (~₹60,000); Price corroborated, confirm before buying
A4: MAHINDRA-BE6SPORTEQ-THREE-59 | B4: V005 | C4: Mahindra | D4: BE 6 SPORTEQ | E4: SUV | F4: Three 59 kWh | G4: battery included | H4: 2195000 | I4: corroborated | J4: 59 | K4: RWD | L4: 5 | M4: 5 | N4: 573 | O4: MIDC Part 1 + Part 2 | P4: 400 | S4: 6.78 | T4: Maker real-world claim (estimate) | U4: =IF(S4="","",((1-Assumptions!$B$4)*Assumptions!$B$2+Assumptions!$B$4*Assumptions!$B$3)/S4) -> 1.3864307 | V4: =IF(U4="","",U4*Assumptions!$B$5*365*Assumptions!$B$6) -> 101209.44 | W4: No | X4: 60000 | Y4: 7.2 kW wall box ₹60,000 (Mahindra XEV 9e/9S pages); BE 6 price assumed same | Z4: =IF(OR(G4<>"battery included",H4="",V4=""),"",H4+X4+V4) -> 2356209.4 | AA4: 455 | AB4: 207 | AC4: 222 | AD4: 6 | AE4: Yes | AF4: None | AG4: 540° | AH4: Panoramic | AI4: Yes | AJ4: No | AK4: 140 | AL4: 106.2 | AM4: =IF(OR(S4="",AL4=""),"",100/S4/AL4*60) -> 8.3329167 | AN4: 8.7 | AO4: 11 | AP4: Lifetime (1st owner) | AQ4: Rated, coverage unconfirmed | AR4: 31.97 | AS4: 45 | AV4: Crash rating may not cover this version; Wall charger not in price (~₹60,000); Price corroborated, confirm before buying
A5: MAHINDRA-BE6SPORTEQ-THREE-70 | B5: V007 | C5: Mahindra | D5: BE 6 SPORTEQ | E5: SUV | F5: Three 70 kWh | G5: battery included | H5: 2295000 | I5: corroborated | J5: 70 | K5: RWD | L5: 5 | M5: 5 | N5: 651 | O5: MIDC Part 1 + Part 2 | P5: 450 | S5: 6.43 | T5: Maker real-world claim (estimate) | U5: =IF(S5="","",((1-Assumptions!$B$4)*Assumptions!$B$2+Assumptions!$B$4*Assumptions!$B$3)/S5) -> 1.4618974 | V5: =IF(U5="","",U5*Assumptions!$B$5*365*Assumptions!$B$6) -> 106718.51 | W5: No | X5: 60000 | Y5: 7.2 kW wall box ₹60,000 (Mahindra XEV 9e/9S pages); BE 6 price assumed same | Z5: =IF(OR(G5<>"battery included",H5="",V5=""),"",H5+X5+V5) -> 2461718.5 | AA5: 455 | AB5: 207 | AC5: 222 | AD5: 6 | AE5: Yes | AF5: None | AG5: 540° | AH5: Panoramic | AI5: Yes | AJ5: No | AK5: 160 | AL5: 126 | AM5: =IF(OR(S5="",AL5=""),"",100/S5/AL5*60) -> 7.4057617 | AN5: 10.2 | AO5: 11 | AP5: Lifetime (1st owner) | AQ5: Rated, coverage unconfirmed | AR5: 31.97 | AS5: 45 | AV5: Crash rating may not cover this version; Wall charger not in price (~₹60,000); Price corroborated, confirm before buying
A6: MAHINDRA-BE6SPORTEQ-THREEPLUS-70 | B6: V009 | C6: Mahindra | D6: BE 6 SPORTEQ | E6: SUV | F6: Three+ 70 kWh | G6: battery included | H6: 2395000 | I6: corroborated | J6: 70 | K6: RWD | L6: 5 | M6: 5 | N6: 651 | O6: MIDC Part 1 + Part 2 | P6: 450 | S6: 6.43 | T6: Maker real-world claim (estimate) | U6: =IF(S6="","",((1-Assumptions!$B$4)*Assumptions!$B$2+Assumptions!$B$4*Assumptions!$B$3)/S6) -> 1.4618974 | V6: =IF(U6="","",U6*Assumptions!$B$5*365*Assumptions!$B$6) -> 106718.51 | W6: No | X6: 60000 | Y6: 7.2 kW wall box ₹60,000 (Mahindra XEV 9e/9S pages); BE 6 price assumed same | Z6: =IF(OR(G6<>"battery included",H6="",V6=""),"",H6+X6+V6) -> 2561718.5 | AA6: 455 | AB6: 207 | AC6: 222 | AD6: 6 | AE6: Yes | AF6: L2 | AG6: 540° | AH6: Panoramic | AI6: Yes | AJ6: No | AK6: 160 | AL6: 126 | AM6: =IF(OR(S6="",AL6=""),"",100/S6/AL6*60) -> 7.4057617 | AN6: 10.2 | AO6: 11 | AP6: Lifetime (1st owner) | AQ6: Rated, coverage unconfirmed | AR6: 31.97 | AS6: 45 | AV6: Crash rating may not cover this version; Wall charger not in price (~₹60,000); Price corroborated, confirm before buying
A7: MAHINDRA-BE6SPORTEQ-FE-79 | B7: V013 | C7: Mahindra | D7: BE 6 SPORTEQ | E7: SUV | F7: FE 79 kWh | G7: battery included | H7: 2445000 | I7: corroborated | J7: 79 | K7: RWD | L7: 5 | M7: 5 | N7: 708 | O7: MIDC Part 1 + Part 2 | P7: 500 | Q7: 449 | R7: 63 | S7: 5.68 | T7: Independent test | U7: =IF(S7="","",((1-Assumptions!$B$4)*Assumptions!$B$2+Assumptions!$B$4*Assumptions!$B$3)/S7) -> 1.6549296 | V7: =IF(U7="","",U7*Assumptions!$B$5*365*Assumptions!$B$6) -> 120809.86 | W7: No | X7: 60000 | Y7: 7.2 kW wall box ₹60,000 (Mahindra XEV 9e/9S pages); BE 6 price assumed same | Z7: =IF(OR(G7<>"battery included",H7="",V7=""),"",H7+X7+V7) -> 2625809.9 | AA7: 455 | AB7: 207 | AC7: 222 | AD7: 6 | AE7: Yes | AF7: None | AG7: 540° | AH7: Panoramic | AI7: No | AJ7: Yes | AK7: 180 | AL7: 142.2 | AM7: =IF(OR(S7="",AL7=""),"",100/S7/AL7*60) -> 7.4285375 | AN7: 11.7 | AO7: 11 | AP7: Lifetime (1st owner) | AQ7: Rated, coverage unconfirmed | AR7: 31.97 | AS7: 45 | AV7: Crash rating may not cover this version; Tested range only 63% of claim; Wall charger not in price (~₹60,000); Price corroborated, confirm before buying
A8: MAHINDRA-BE6SPORTEQ-THREEPLUS-79 | B8: V011 | C8: Mahindra | D8: BE 6 SPORTEQ | E8: SUV | F8: Three+ 79 kWh | G8: battery included | H8: 2495000 | I8: corroborated | J8: 79 | K8: RWD | L8: 5 | M8: 5 | N8: 708 | O8: MIDC Part 1 + Part 2 | P8: 500 | Q8: 449 | R8: 63 | S8: 5.68 | T8: Independent test | U8: =IF(S8="","",((1-Assumptions!$B$4)*Assumptions!$B$2+Assumptions!$B$4*Assumptions!$B$3)/S8) -> 1.6549296 | V8: =IF(U8="","",U8*Assumptions!$B$5*365*Assumptions!$B$6) -> 120809.86 | W8: No | X8: 60000 | Y8: 7.2 kW wall box ₹60,000 (Mahindra XEV 9e/9S pages); BE 6 price assumed same | Z8: =IF(OR(G8<>"battery included",H8="",V8=""),"",H8+X8+V8) -> 2675809.9 | AA8: 455 | AB8: 207 | AC8: 222 | AD8: 6 | AE8: Yes | AF8: L2 | AG8: 540° | AH8: Panoramic | AI8: Yes | AJ8: No | AK8: 180 | AL8: 142.2 | AM8: =IF(OR(S8="",AL8=""),"",100/S8/AL8*60) -> 7.4285375 | AN8: 11.7 | AO8: 11 | AP8: Lifetime (1st owner) | AQ8: Rated, coverage unconfirmed | AR8: 31.97 | AS8: 45 | AV8: Crash rating may not cover this version; Tested range only 63% of claim; Wall charger not in price (~₹60,000); Price corroborated, confirm before buying
A9: MAHINDRA-BE6SPORTEQ-FOUR-79 | B9: V015 | C9: Mahindra | D9: BE 6 SPORTEQ | E9: SUV | F9: Four 79 kWh | G9: battery included | H9: 2695000 | I9: corroborated | J9: 79 | K9: RWD | L9: 5 | M9: 5 | N9: 708 | O9: MIDC Part 1 + Part 2 | P9: 500 | Q9: 449 | R9: 63 | S9: 5.68 | T9: Independent test | U9: =IF(S9="","",((1-Assumptions!$B$4)*Assumptions!$B$2+Assumptions!$B$4*Assumptions!$B$3)/S9) -> 1.6549296 | V9: =IF(U9="","",U9*Assumptions!$B$5*365*Assumptions!$B$6) -> 120809.86 | W9: No | X9: 60000 | Y9: 7.2 kW wall box ₹60,000 (Mahindra XEV 9e/9S pages); BE 6 price assumed same | Z9: =IF(OR(G9<>"battery included",H9="",V9=""),"",H9+X9+V9) -> 2875809.9 | AA9: 455 | AB9: 207 | AC9: 222 | AD9: 6 | AE9: Yes | AF9: L2+ | AG9: 540° | AH9: Panoramic | AI9: Yes | AJ9: Yes | AK9: 180 | AL9: 142.2 | AM9: =IF(OR(S9="",AL9=""),"",100/S9/AL9*60) -> 7.4285375 | AN9: 11.7 | AO9: 11 | AP9: Lifetime (1st owner) | AQ9: Rated, coverage unconfirmed | AR9: 31.97 | AS9: 45 | AV9: Crash rating may not cover this version; Tested range only 63% of claim; Wall charger not in price (~₹60,000); Price corroborated, confirm before buying
A10: MAHINDRA-BE6SPORTEQ-FEFOUR-79 | B10: V017 | C10: Mahindra | D10: BE 6 SPORTEQ | E10: SUV | F10: FE Four 79 kWh | G10: battery included | H10: 2695000 | I10: corroborated | J10: 79 | K10: RWD | L10: 5 | M10: 5 | N10: 708 | O10: MIDC Part 1 + Part 2 | P10: 500 | Q10: 449 | R10: 63 | S10: 5.68 | T10: Independent test | U10: =IF(S10="","",((1-Assumptions!$B$4)*Assumptions!$B$2+Assumptions!$B$4*Assumptions!$B$3)/S10) -> 1.6549296 | V10: =IF(U10="","",U10*Assumptions!$B$5*365*Assumptions!$B$6) -> 120809.86 | W10: No | X10: 60000 | Y10: 7.2 kW wall box ₹60,000 (Mahindra XEV 9e/9S pages); BE 6 price assumed same | Z10: =IF(OR(G10<>"battery included",H10="",V10=""),"",H10+X10+V10) -> 2875809.9 | AA10: 455 | AB10: 207 | AC10: 222 | AD10: 6 | AE10: Yes | AF10: L2+ | AG10: 540° | AH10: Panoramic | AI10: Not stated | AJ10: Yes | AK10: 180 | AL10: 142.2 | AM10: =IF(OR(S10="",AL10=""),"",100/S10/AL10*60) -> 7.4285375 | AN10: 11.7 | AO10: 11 | AP10: Lifetime (1st owner) | AQ10: Rated, coverage unconfirmed | AR10: 31.97 | AS10: 45 | AV10: Crash rating may not cover this version; Tested range only 63% of claim; Wall charger not in price (~₹60,000); Price corroborated, confirm before buying
A11: MAHINDRA-BE6SPORTEQ-LAUNCHEDITION-79 | B11: V019 | C11: Mahindra | D11: BE 6 SPORTEQ | E11: SUV | F11: Launch Edition 79 kWh | G11: battery included | H11: 2695000 | I11: corroborated | J11: 79 | K11: RWD | L11: 5 | M11: 5 | N11: 708 | O11: MIDC Part 1 + Part 2 | P11: 500 | Q11: 449 | R11: 63 | S11: 5.68 | T11: Independent test | U11: =IF(S11="","",((1-Assumptions!$B$4)*Assumptions!$B$2+Assumptions!$B$4*Assumptions!$B$3)/S11) -> 1.6549296 | V11: =IF(U11="","",U11*Assumptions!$B$5*365*Assumptions!$B$6) -> 120809.86 | W11: No | X11: 60000 | Y11: 7.2 kW wall box ₹60,000 (Mahindra XEV 9e/9S pages); BE 6 price assumed same | Z11: =IF(OR(G11<>"battery included",H11="",V11=""),"",H11+X11+V11) -> 2875809.9 | AA11: 455 | AB11: 207 | AC11: 222 | AD11: 6 | AE11: Yes | AF11: L2+ | AG11: 540° | AH11: Panoramic | AI11: Yes | AJ11: Yes | AK11: 180 | AL11: 142.2 | AM11: =IF(OR(S11="",AL11=""),"",100/S11/AL11*60) -> 7.4285375 | AN11: 11.7 | AO11: 11 | AP11: Lifetime (1st owner) | AQ11: Rated, coverage unconfirmed | AR11: 31.97 | AS11: 45 | AV11: Crash rating may not cover this version; Tested range only 63% of claim; Wall charger not in price (~₹60,000); Price corroborated, confirm before buying
A12: MAHINDRA-BE6SPORTEQ-ONE-59-BAAS | B12: V002 | C12: Mahindra | D12: BE 6 SPORTEQ | E12: SUV | F12: One 59 kWh BaaS | G12: BaaS | H12: 1145000 | I12: verified | J12: 59 | K12: RWD | L12: 5 | M12: 5 | N12: 573 | O12: MIDC Part 1 + Part 2 | P12: 400 | S12: 6.78 | T12: Maker real-world claim (estimate) | U12: =IF(S12="","",((1-Assumptions!$B$4)*Assumptions!$B$2+Assumptions!$B$4*Assumptions!$B$3)/S12) -> 1.3864307 | V12: =IF(U12="","",U12*Assumptions!$B$5*365*Assumptions!$B$6) -> 101209.44 | W12: No | X12: 60000 | Y12: 7.2 kW wall box ₹60,000 (Mahindra XEV 9e/9S pages); BE 6 price assumed same | Z12: =IF(OR(G12<>"battery included",H12="",V12=""),"",H12+X12+V12) | AA12: 455 | AB12: 207 | AC12: 222 | AD12: 6 | AE12: Yes | AF12: None | AG12: Rear camera | AH12: None | AI12: No | AJ12: No | AK12: 140 | AL12: 106.2 | AM12: =IF(OR(S12="",AL12=""),"",100/S12/AL12*60) -> 8.3329167 | AN12: 8.7 | AO12: 11 | AP12: Lifetime (1st owner) | AQ12: Rated, coverage unconfirmed | AR12: 31.97 | AS12: 45 | AV12: Crash rating may not cover this version; BaaS: battery paid via separate loan (up to 8 yrs); not pay-per-km
A13: MAHINDRA-BE6SPORTEQ-TWO-59-BAAS | B13: V004 | C13: Mahindra | D13: BE 6 SPORTEQ | E13: SUV | F13: Two 59 kWh BaaS | G13: BaaS | H13: 1295000 | I13: verified | J13: 59 | K13: RWD | L13: 5 | M13: 5 | N13: 573 | O13: MIDC Part 1 + Part 2 | P13: 400 | S13: 6.78 | T13: Maker real-world claim (estimate) | U13: =IF(S13="","",((1-Assumptions!$B$4)*Assumptions!$B$2+Assumptions!$B$4*Assumptions!$B$3)/S13) -> 1.3864307 | V13: =IF(U13="","",U13*Assumptions!$B$5*365*Assumptions!$B$6) -> 101209.44 | W13: No | X13: 60000 | Y13: 7.2 kW wall box ₹60,000 (Mahindra XEV 9e/9S pages); BE 6 price assumed same | Z13: =IF(OR(G13<>"battery included",H13="",V13=""),"",H13+X13+V13) | AA13: 455 | AB13: 207 | AC13: 222 | AD13: 6 | AE13: Yes | AF13: None | AG13: 540° | AH13: None | AI13: No | AJ13: No | AK13: 140 | AL13: 106.2 | AM13: =IF(OR(S13="",AL13=""),"",100/S13/AL13*60) -> 8.3329167 | AN13: 8.7 | AO13: 11 | AP13: Lifetime (1st owner) | AQ13: Rated, coverage unconfirmed | AR13: 31.97 | AS13: 45 | AV13: Crash rating may not cover this version; BaaS: battery paid via separate loan (up to 8 yrs); not pay-per-km
A14: MAHINDRA-BE6SPORTEQ-THREE-59-BAAS | B14: V006 | C14: Mahindra | D14: BE 6 SPORTEQ | E14: SUV | F14: Three 59 kWh BaaS | G14: BaaS | H14: 1395000 | I14: verified | J14: 59 | K14: RWD | L14: 5 | M14: 5 | N14: 573 | O14: MIDC Part 1 + Part 2 | P14: 400 | S14: 6.78 | T14: Maker real-world claim (estimate) | U14: =IF(S14="","",((1-Assumptions!$B$4)*Assumptions!$B$2+Assumptions!$B$4*Assumptions!$B$3)/S14) -> 1.3864307 | V14: =IF(U14="","",U14*Assumptions!$B$5*365*Assumptions!$B$6) -> 101209.44 | W14: No | X14: 60000 | Y14: 7.2 kW wall box ₹60,000 (Mahindra XEV 9e/9S pages); BE 6 price assumed same | Z14: =IF(OR(G14<>"battery included",H14="",V14=""),"",H14+X14+V14) | AA14: 455 | AB14: 207 | AC14: 222 | AD14: 6 | AE14: Yes | AF14: None | AG14: 540° | AH14: Panoramic | AI14: Yes | AJ14: No | AK14: 140 | AL14: 106.2 | AM14: =IF(OR(S14="",AL14=""),"",100/S14/AL14*60) -> 8.3329167 | AN14: 8.7 | AO14: 11 | AP14: Lifetime (1st owner) | AQ14: Rated, coverage unconfirmed | AR14: 31.97 | AS14: 45 | AV14: Crash rating may not cover this version; BaaS: battery paid via separate loan (up to 8 yrs); not pay-per-km
A15: MAHINDRA-BE6SPORTEQ-THREE-70-BAAS | B15: V008 | C15: Mahindra | D15: BE 6 SPORTEQ | E15: SUV | F15: Three 70 kWh BaaS | G15: BaaS | H15: 1395000 | I15: verified | J15: 70 | K15: RWD | L15: 5 | M15: 5 | N15: 651 | O15: MIDC Part 1 + Part 2 | P15: 450 | S15: 6.43 | T15: Maker real-world claim (estimate) | U15: =IF(S15="","",((1-Assumptions!$B$4)*Assumptions!$B$2+Assumptions!$B$4*Assumptions!$B$3)/S15) -> 1.4618974 | V15: =IF(U15="","",U15*Assumptions!$B$5*365*Assumptions!$B$6) -> 106718.51 | W15: No | X15: 60000 | Y15: 7.2 kW wall box ₹60,000 (Mahindra XEV 9e/9S pages); BE 6 price assumed same | Z15: =IF(OR(G15<>"battery included",H15="",V15=""),"",H15+X15+V15) | AA15: 455 | AB15: 207 | AC15: 222 | AD15: 6 | AE15: Yes | AF15: None | AG15: 540° | AH15: Panoramic | AI15: Yes | AJ15: No | AK15: 160 | AL15: 126 | AM15: =IF(OR(S15="",AL15=""),"",100/S15/AL15*60) -> 7.4057617 | AN15: 10.2 | AO15: 11 | AP15: Lifetime (1st owner) | AQ15: Rated, coverage unconfirmed | AR15: 31.97 | AS15: 45 | AV15: Crash rating may not cover this version; BaaS: battery paid via separate loan (up to 8 yrs); not pay-per-km
A16: MAHINDRA-BE6SPORTEQ-FE-79-BAAS | B16: V014 | C16: Mahindra | D16: BE 6 SPORTEQ | E16: SUV | F16: FE 79 kWh BaaS | G16: BaaS | H16: 1445000 | I16: verified | J16: 79 | K16: RWD | L16: 5 | M16: 5 | N16: 708 | O16: MIDC Part 1 + Part 2 | P16: 500 | Q16: 449 | R16: 63 | S16: 5.68 | T16: Independent test | U16: =IF(S16="","",((1-Assumptions!$B$4)*Assumptions!$B$2+Assumptions!$B$4*Assumptions!$B$3)/S16) -> 1.6549296 | V16: =IF(U16="","",U16*Assumptions!$B$5*365*Assumptions!$B$6) -> 120809.86 | W16: No | X16: 60000 | Y16: 7.2 kW wall box ₹60,000 (Mahindra XEV 9e/9S pages); BE 6 price assumed same | Z16: =IF(OR(G16<>"battery included",H16="",V16=""),"",H16+X16+V16) | AA16: 455 | AB16: 207 | AC16: 222 | AD16: 6 | AE16: Yes | AF16: None | AG16: 540° | AH16: Panoramic | AI16: No | AJ16: Yes | AK16: 180 | AL16: 142.2 | AM16: =IF(OR(S16="",AL16=""),"",100/S16/AL16*60) -> 7.4285375 | AN16: 11.7 | AO16: 11 | AP16: Lifetime (1st owner) | AQ16: Rated, coverage unconfirmed | AR16: 31.97 | AS16: 45 | AV16: Crash rating may not cover this version; Tested range only 63% of claim; BaaS: battery paid via separate loan (up to 8 yrs); not pay-per-km
A17: MAHINDRA-BE6SPORTEQ-THREEPLUS-70-BAAS | B17: V010 | C17: Mahindra | D17: BE 6 SPORTEQ | E17: SUV | F17: Three+ 70 kWh BaaS | G17: BaaS | H17: 1495000 | I17: verified | J17: 70 | K17: RWD | L17: 5 | M17: 5 | N17: 651 | O17: MIDC Part 1 + Part 2 | P17: 450 | S17: 6.43 | T17: Maker real-world claim (estimate) | U17: =IF(S17="","",((1-Assumptions!$B$4)*Assumptions!$B$2+Assumptions!$B$4*Assumptions!$B$3)/S17) -> 1.4618974 | V17: =IF(U17="","",U17*Assumptions!$B$5*365*Assumptions!$B$6) -> 106718.51 | W17: No | X17: 60000 | Y17: 7.2 kW wall box ₹60,000 (Mahindra XEV 9e/9S pages); BE 6 price assumed same | Z17: =IF(OR(G17<>"battery included",H17="",V17=""),"",H17+X17+V17) | AA17: 455 | AB17: 207 | AC17: 222 | AD17: 6 | AE17: Yes | AF17: L2 | AG17: 540° | AH17: Panoramic | AI17: Yes | AJ17: No | AK17: 160 | AL17: 126 | AM17: =IF(OR(S17="",AL17=""),"",100/S17/AL17*60) -> 7.4057617 | AN17: 10.2 | AO17: 11 | AP17: Lifetime (1st owner) | AQ17: Rated, coverage unconfirmed | AR17: 31.97 | AS17: 45 | AV17: Crash rating may not cover this version; BaaS: battery paid via separate loan (up to 8 yrs); not pay-per-km
A18: MAHINDRA-BE6SPORTEQ-THREEPLUS-79-BAAS | B18: V012 | C18: Mahindra | D18: BE 6 SPORTEQ | E18: SUV | F18: Three+ 79 kWh BaaS | G18: BaaS | H18: 1495000 | I18: verified | J18: 79 | K18: RWD | L18: 5 | M18: 5 | N18: 708 | O18: MIDC Part 1 + Part 2 | P18: 500 | Q18: 449 | R18: 63 | S18: 5.68 | T18: Independent test | U18: =IF(S18="","",((1-Assumptions!$B$4)*Assumptions!$B$2+Assumptions!$B$4*Assumptions!$B$3)/S18) -> 1.6549296 | V18: =IF(U18="","",U18*Assumptions!$B$5*365*Assumptions!$B$6) -> 120809.86 | W18: No | X18: 60000 | Y18: 7.2 kW wall box ₹60,000 (Mahindra XEV 9e/9S pages); BE 6 price assumed same | Z18: =IF(OR(G18<>"battery included",H18="",V18=""),"",H18+X18+V18) | AA18: 455 | AB18: 207 | AC18: 222 | AD18: 6 | AE18: Yes | AF18: L2 | AG18: 540° | AH18: Panoramic | AI18: Yes | AJ18: No | AK18: 180 | AL18: 142.2 | AM18: =IF(OR(S18="",AL18=""),"",100/S18/AL18*60) -> 7.4285375 | AN18: 11.7 | AO18: 11 | AP18: Lifetime (1st owner) | AQ18: Rated, coverage unconfirmed | AR18: 31.97 | AS18: 45 | AV18: Crash rating may not cover this version; Tested range only 63% of claim; BaaS: battery paid via separate loan (up to 8 yrs); not pay-per-km
A19: MAHINDRA-BE6SPORTEQ-FOUR-79-BAAS | B19: V016 | C19: Mahindra | D19: BE 6 SPORTEQ | E19: SUV | F19: Four 79 kWh BaaS | G19: BaaS | H19: 1695000 | I19: verified | J19: 79 | K19: RWD | L19: 5 | M19: 5 | N19: 708 | O19: MIDC Part 1 + Part 2 | P19: 500 | Q19: 449 | R19: 63 | S19: 5.68 | T19: Independent test | U19: =IF(S19="","",((1-Assumptions!$B$4)*Assumptions!$B$2+Assumptions!$B$4*Assumptions!$B$3)/S19) -> 1.6549296 | V19: =IF(U19="","",U19*Assumptions!$B$5*365*Assumptions!$B$6) -> 120809.86 | W19: No | X19: 60000 | Y19: 7.2 kW wall box ₹60,000 (Mahindra XEV 9e/9S pages); BE 6 price assumed same | Z19: =IF(OR(G19<>"battery included",H19="",V19=""),"",H19+X19+V19) | AA19: 455 | AB19: 207 | AC19: 222 | AD19: 6 | AE19: Yes | AF19: L2+ | AG19: 540° | AH19: Panoramic | AI19: Yes | AJ19: Yes | AK19: 180 | AL19: 142.2 | AM19: =IF(OR(S19="",AL19=""),"",100/S19/AL19*60) -> 7.4285375 | AN19: 11.7 | AO19: 11 | AP19: Lifetime (1st owner) | AQ19: Rated, coverage unconfirmed | AR19: 31.97 | AS19: 45 | AV19: Crash rating may not cover this version; Tested range only 63% of claim; BaaS: battery paid via separate loan (up to 8 yrs); not pay-per-km
A20: MAHINDRA-BE6SPORTEQ-FEFOUR-79-BAAS | B20: V018 | C20: Mahindra | D20: BE 6 SPORTEQ | E20: SUV | F20: FE Four 79 kWh BaaS | G20: BaaS | H20: 1695000 | I20: verified | J20: 79 | K20: RWD | L20: 5 | M20: 5 | N20: 708 | O20: MIDC Part 1 + Part 2 | P20: 500 | Q20: 449 | R20: 63 | S20: 5.68 | T20: Independent test | U20: =IF(S20="","",((1-Assumptions!$B$4)*Assumptions!$B$2+Assumptions!$B$4*Assumptions!$B$3)/S20) -> 1.6549296 | V20: =IF(U20="","",U20*Assumptions!$B$5*365*Assumptions!$B$6) -> 120809.86 | W20: No | X20: 60000 | Y20: 7.2 kW wall box ₹60,000 (Mahindra XEV 9e/9S pages); BE 6 price assumed same | Z20: =IF(OR(G20<>"battery included",H20="",V20=""),"",H20+X20+V20) | AA20: 455 | AB20: 207 | AC20: 222 | AD20: 6 | AE20: Yes | AF20: L2+ | AG20: 540° | AH20: Panoramic | AI20: Not stated | AJ20: Yes | AK20: 180 | AL20: 142.2 | AM20: =IF(OR(S20="",AL20=""),"",100/S20/AL20*60) -> 7.4285375 | AN20: 11.7 | AO20: 11 | AP20: Lifetime (1st owner) | AQ20: Rated, coverage unconfirmed | AR20: 31.97 | AS20: 45 | AV20: Crash rating may not cover this version; Tested range only 63% of claim; BaaS: battery paid via separate loan (up to 8 yrs); not pay-per-km
A21: MAHINDRA-BE6SPORTEQ-LAUNCHEDITION-79-BAAS | B21: V020 | C21: Mahindra | D21: BE 6 SPORTEQ | E21: SUV | F21: Launch Edition 79 kWh BaaS | G21: BaaS | H21: 1695000 | I21: verified | J21: 79 | K21: RWD | L21: 5 | M21: 5 | N21: 708 | O21: MIDC Part 1 + Part 2 | P21: 500 | Q21: 449 | R21: 63 | S21: 5.68 | T21: Independent test | U21: =IF(S21="","",((1-Assumptions!$B$4)*Assumptions!$B$2+Assumptions!$B$4*Assumptions!$B$3)/S21) -> 1.6549296 | V21: =IF(U21="","",U21*Assumptions!$B$5*365*Assumptions!$B$6) -> 120809.86 | W21: No | X21: 60000 | Y21: 7.2 kW wall box ₹60,000 (Mahindra XEV 9e/9S pages); BE 6 price assumed same | Z21: =IF(OR(G21<>"battery included",H21="",V21=""),"",H21+X21+V21) | AA21: 455 | AB21: 207 | AC21: 222 | AD21: 6 | AE21: Yes | AF21: L2+ | AG21: 540° | AH21: Panoramic | AI21: Yes | AJ21: Yes | AK21: 180 | AL21: 142.2 | AM21: =IF(OR(S21="",AL21=""),"",100/S21/AL21*60) -> 7.4285375 | AN21: 11.7 | AO21: 11 | AP21: Lifetime (1st owner) | AQ21: Rated, coverage unconfirmed | AR21: 31.97 | AS21: 45 | AV21: Crash rating may not cover this version; Tested range only 63% of claim; BaaS: battery paid via separate loan (up to 8 yrs); not pay-per-km
A22: MAHINDRA-XEV9S-PACKONEABOVE-59 | B22: V033 | C22: Mahindra | D22: XEV 9S | E22: SUV | F22: Pack One Above 59 kWh | G22: battery included | H22: 2065000 | I22: corroborated | J22: 59 | K22: RWD | L22: 7 | M22: 7 | N22: 521 | O22: MIDC Part 1 + Part 2 | P22: 400 | S22: 6.78 | T22: Maker real-world claim (estimate) | U22: =IF(S22="","",((1-Assumptions!$B$4)*Assumptions!$B$2+Assumptions!$B$4*Assumptions!$B$3)/S22) -> 1.3864307 | V22: =IF(U22="","",U22*Assumptions!$B$5*365*Assumptions!$B$6) -> 101209.44 | W22: No | X22: 60000 | Y22: 7.2 kW wall box ₹60,000 (Mahindra XEV 9e/9S pages) | Z22: =IF(OR(G22<>"battery included",H22="",V22=""),"",H22+X22+V22) -> 2226209.4 | AA22: 527 | AB22: 205 | AC22: 222 | AD22: 6 | AE22: Yes | AF22: None | AG22: Rear camera | AH22: Openable panoramic | AI22: No | AJ22: No | AK22: 140 | AL22: 106.2 | AM22: =IF(OR(S22="",AL22=""),"",100/S22/AL22*60) -> 8.3329167 | AN22: 8.7 | AO22: 11 | AP22: Lifetime (1st owner) | AQ22: Not tested | AV22: No Bharat NCAP crash test; Wall charger not in price (~₹60,000); Price corroborated, confirm before buying
A23: MAHINDRA-XEV9S-PACKONEABOVE-79 | B23: V035 | C23: Mahindra | D23: XEV 9S | E23: SUV | F23: Pack One Above 79 kWh | G23: battery included | H23: 2265000 | I23: corroborated | J23: 79 | K23: RWD | L23: 7 | M23: 7 | N23: 679 | O23: MIDC Part 1 + Part 2 | P23: 500 | Q23: 478 | R23: 70 | S23: 6.33 | T23: Maker real-world claim (estimate) | U23: =IF(S23="","",((1-Assumptions!$B$4)*Assumptions!$B$2+Assumptions!$B$4*Assumptions!$B$3)/S23) -> 1.4849921 | V23: =IF(U23="","",U23*Assumptions!$B$5*365*Assumptions!$B$6) -> 108404.42 | W23: No | X23: 60000 | Y23: 7.2 kW wall box ₹60,000 (Mahindra XEV 9e/9S pages) | Z23: =IF(OR(G23<>"battery included",H23="",V23=""),"",H23+X23+V23) -> 2433404.4 | AA23: 527 | AB23: 205 | AC23: 222 | AD23: 6 | AE23: Yes | AF23: None | AG23: Rear camera | AH23: Openable panoramic | AI23: No | AJ23: No | AK23: 180 | AL23: 142.2 | AM23: =IF(OR(S23="",AL23=""),"",100/S23/AL23*60) -> 6.6657335 | AN23: 11.7 | AO23: 11 | AP23: Lifetime (1st owner) | AQ23: Not tested | AV23: No Bharat NCAP crash test; Wall charger not in price (~₹60,000); Price corroborated, confirm before buying
A24: MAHINDRA-XEV9S-PACKTWOABOVE-70 | B24: V037 | C24: Mahindra | D24: XEV 9S | E24: SUV | F24: Pack Two Above 70 kWh (7-seater) | G24: battery included | H24: 2505000 | I24: corroborated | J24: 70 | K24: RWD | L24: 7 | M24: 7 | N24: 600 | O24: MIDC Part 1 + Part 2 | P24: 450 | S24: 6.43 | T24: Maker real-world claim (estimate) | U24: =IF(S24="","",((1-Assumptions!$B$4)*Assumptions!$B$2+Assumptions!$B$4*Assumptions!$B$3)/S24) -> 1.4618974 | V24: =IF(U24="","",U24*Assumptions!$B$5*365*Assumptions!$B$6) -> 106718.51 | W24: No | X24: 60000 | Y24: 7.2 kW wall box ₹60,000 (Mahindra XEV 9e/9S pages) | Z24: =IF(OR(G24<>"battery included",H24="",V24=""),"",H24+X24+V24) -> 2671718.5 | AA24: 527 | AB24: 205 | AC24: 222 | AD24: 6 | AE24: Yes | AF24: L2 | AG24: 360° | AH24: Openable panoramic | AI24: Yes | AJ24: No | AK24: 160 | AL24: 126 | AM24: =IF(OR(S24="",AL24=""),"",100/S24/AL24*60) -> 7.4057617 | AN24: 10.2 | AO24: 11 | AP24: Lifetime (1st owner) | AQ24: Not tested | AV24: No Bharat NCAP crash test; Wall charger not in price (~₹60,000); Price corroborated, confirm before buying
A25: MAHINDRA-XEV9S-PACKTWOABOVE-70-6S | B25: V084 | C25: Mahindra | D25: XEV 9S | E25: SUV | F25: Pack Two Above 70 kWh (6-seater) | G25: battery included | H25: 2525000 | I25: corroborated | J25: 70 | K25: RWD | L25: 6 | M25: 6 | N25: 600 | O25: MIDC Part 1 + Part 2 | P25: 450 | S25: 6.43 | T25: Maker real-world claim (estimate) | U25: =IF(S25="","",((1-Assumptions!$B$4)*Assumptions!$B$2+Assumptions!$B$4*Assumptions!$B$3)/S25) -> 1.4618974 | V25: =IF(U25="","",U25*Assumptions!$B$5*365*Assumptions!$B$6) -> 106718.51 | W25: No | X25: 60000 | Y25: 7.2 kW wall box ₹60,000 (Mahindra XEV 9e/9S pages) | Z25: =IF(OR(G25<>"battery included",H25="",V25=""),"",H25+X25+V25) -> 2691718.5 | AA25: 527 | AB25: 205 | AC25: 222 | AD25: 6 | AE25: Yes | AF25: L2 | AG25: 360° | AH25: Openable panoramic | AI25: Yes | AJ25: No | AK25: 160 | AL25: 126 | AM25: =IF(OR(S25="",AL25=""),"",100/S25/AL25*60) -> 7.4057617 | AN25: 10.2 | AO25: 11 | AP25: Lifetime (1st owner) | AQ25: Not tested | AV25: No Bharat NCAP crash test; Wall charger not in price (~₹60,000); Price corroborated, confirm before buying
A26: MAHINDRA-XEV9S-PACKTWOABOVE-79 | B26: V039 | C26: Mahindra | D26: XEV 9S | E26: SUV | F26: Pack Two Above 79 kWh (7-seater) | G26: battery included | H26: 2595000 | I26: corroborated | J26: 79 | K26: RWD | L26: 7 | M26: 7 | N26: 679 | O26: MIDC Part 1 + Part 2 | P26: 500 | Q26: 478 | R26: 70 | S26: 6.33 | T26: Maker real-world claim (estimate) | U26: =IF(S26="","",((1-Assumptions!$B$4)*Assumptions!$B$2+Assumptions!$B$4*Assumptions!$B$3)/S26) -> 1.4849921 | V26: =IF(U26="","",U26*Assumptions!$B$5*365*Assumptions!$B$6) -> 108404.42 | W26: No | X26: 60000 | Y26: 7.2 kW wall box ₹60,000 (Mahindra XEV 9e/9S pages) | Z26: =IF(OR(G26<>"battery included",H26="",V26=""),"",H26+X26+V26) -> 2763404.4 | AA26: 527 | AB26: 205 | AC26: 222 | AD26: 6 | AE26: Yes | AF26: L2 | AG26: 360° | AH26: Openable panoramic | AI26: Yes | AJ26: No | AK26: 180 | AL26: 142.2 | AM26: =IF(OR(S26="",AL26=""),"",100/S26/AL26*60) -> 6.6657335 | AN26: 11.7 | AO26: 11 | AP26: Lifetime (1st owner) | AQ26: Not tested | AV26: No Bharat NCAP crash test; Wall charger not in price (~₹60,000); Price corroborated, confirm before buying
A27: MAHINDRA-XEV9S-PACKTWOABOVE-79-6S | B27: V085 | C27: Mahindra | D27: XEV 9S | E27: SUV | F27: Pack Two Above 79 kWh (6-seater) | G27: battery included | H27: 2615000 | I27: corroborated | J27: 79 | K27: RWD | L27: 6 | M27: 6 | N27: 679 | O27: MIDC Part 1 + Part 2 | P27: 500 | Q27: 478 | R27: 70 | S27: 6.33 | T27: Maker real-world claim (estimate) | U27: =IF(S27="","",((1-Assumptions!$B$4)*Assumptions!$B$2+Assumptions!$B$4*Assumptions!$B$3)/S27) -> 1.4849921 | V27: =IF(U27="","",U27*Assumptions!$B$5*365*Assumptions!$B$6) -> 108404.42 | W27: No | X27: 60000 | Y27: 7.2 kW wall box ₹60,000 (Mahindra XEV 9e/9S pages) | Z27: =IF(OR(G27<>"battery included",H27="",V27=""),"",H27+X27+V27) -> 2783404.4 | AA27: 527 | AB27: 205 | AC27: 222 | AD27: 6 | AE27: Yes | AF27: L2 | AG27: 360° | AH27: Openable panoramic | AI27: Yes | AJ27: No | AK27: 180 | AL27: 142.2 | AM27: =IF(OR(S27="",AL27=""),"",100/S27/AL27*60) -> 6.6657335 | AN27: 11.7 | AO27: 11 | AP27: Lifetime (1st owner) | AQ27: Not tested | AV27: No Bharat NCAP crash test; Wall charger not in price (~₹60,000); Price corroborated, confirm before buying
A28: MAHINDRA-XEV9S-PACKTHREE-79 | B28: V041 | C28: Mahindra | D28: XEV 9S | E28: SUV | F28: Pack Three 79 kWh (7-seater) | G28: battery included | H28: 2785000 | I28: corroborated | J28: 79 | K28: RWD | L28: 7 | M28: 7 | N28: 679 | O28: MIDC Part 1 + Part 2 | P28: 500 | Q28: 478 | R28: 70 | S28: 6.33 | T28: Maker real-world claim (estimate) | U28: =IF(S28="","",((1-Assumptions!$B$4)*Assumptions!$B$2+Assumptions!$B$4*Assumptions!$B$3)/S28) -> 1.4849921 | V28: =IF(U28="","",U28*Assumptions!$B$5*365*Assumptions!$B$6) -> 108404.42 | W28: No | X28: 60000 | Y28: 7.2 kW wall box ₹60,000 (Mahindra XEV 9e/9S pages) | Z28: =IF(OR(G28<>"battery included",H28="",V28=""),"",H28+X28+V28) -> 2953404.4 | AA28: 527 | AB28: 205 | AC28: 222 | AD28: 7 | AE28: Yes | AF28: L2+ | AG28: 360° | AH28: Openable panoramic | AI28: Yes | AJ28: Yes | AK28: 180 | AL28: 142.2 | AM28: =IF(OR(S28="",AL28=""),"",100/S28/AL28*60) -> 6.6657335 | AN28: 11.7 | AO28: 11 | AP28: Lifetime (1st owner) | AQ28: Not tested | AV28: No Bharat NCAP crash test; Wall charger not in price (~₹60,000); Price corroborated, confirm before buying
A29: MAHINDRA-XEV9S-PACKTHREE-79-6S | B29: V086 | C29: Mahindra | D29: XEV 9S | E29: SUV | F29: Pack Three 79 kWh (6-seater) | G29: battery included | H29: 2805000 | I29: corroborated | J29: 79 | K29: RWD | L29: 6 | M29: 6 | N29: 679 | O29: MIDC Part 1 + Part 2 | P29: 500 | Q29: 478 | R29: 70 | S29: 6.33 | T29: Maker real-world claim (estimate) | U29: =IF(S29="","",((1-Assumptions!$B$4)*Assumptions!$B$2+Assumptions!$B$4*Assumptions!$B$3)/S29) -> 1.4849921 | V29: =IF(U29="","",U29*Assumptions!$B$5*365*Assumptions!$B$6) -> 108404.42 | W29: No | X29: 60000 | Y29: 7.2 kW wall box ₹60,000 (Mahindra XEV 9e/9S pages) | Z29: =IF(OR(G29<>"battery included",H29="",V29=""),"",H29+X29+V29) -> 2973404.4 | AA29: 527 | AB29: 205 | AC29: 222 | AD29: 7 | AE29: Yes | AF29: L2+ | AG29: 360° | AH29: Openable panoramic | AI29: Yes | AJ29: Yes | AK29: 180 | AL29: 142.2 | AM29: =IF(OR(S29="",AL29=""),"",100/S29/AL29*60) -> 6.6657335 | AN29: 11.7 | AO29: 11 | AP29: Lifetime (1st owner) | AQ29: Not tested | AV29: No Bharat NCAP crash test; Wall charger not in price (~₹60,000); Price corroborated, confirm before buying
A30: MAHINDRA-XEV9S-PACKTHREEABOVE-79 | B30: V087 | C30: Mahindra | D30: XEV 9S | E30: SUV | F30: Pack Three Above 79 kWh (7-seater) | G30: battery included | H30: 2995000 | I30: corroborated | J30: 79 | K30: RWD | L30: 7 | M30: 7 | N30: 679 | O30: MIDC Part 1 + Part 2 | P30: 500 | Q30: 478 | R30: 70 | S30: 6.33 | T30: Maker real-world claim (estimate) | U30: =IF(S30="","",((1-Assumptions!$B$4)*Assumptions!$B$2+Assumptions!$B$4*Assumptions!$B$3)/S30) -> 1.4849921 | V30: =IF(U30="","",U30*Assumptions!$B$5*365*Assumptions!$B$6) -> 108404.42 | W30: No | X30: 60000 | Y30: 7.2 kW wall box ₹60,000 (Mahindra XEV 9e/9S pages) | Z30: =IF(OR(G30<>"battery included",H30="",V30=""),"",H30+X30+V30) -> 3163404.4 | AA30: 527 | AB30: 205 | AC30: 222 | AD30: 7 | AE30: Yes | AF30: L2+ | AG30: 360° | AH30: Openable panoramic | AI30: Yes | AJ30: Yes | AK30: 180 | AL30: 142.2 | AM30: =IF(OR(S30="",AL30=""),"",100/S30/AL30*60) -> 6.6657335 | AN30: 11.7 | AO30: 11 | AP30: Lifetime (1st owner) | AQ30: Not tested | AV30: No Bharat NCAP crash test; Wall charger not in price (~₹60,000); Price corroborated, confirm before buying
A31: MAHINDRA-XEV9S-PACKTHREEABOVE-79-6S | B31: V043 | C31: Mahindra | D31: XEV 9S | E31: SUV | F31: Pack Three Above 79 kWh (6-seater) | G31: battery included | H31: 3015000 | I31: verified | J31: 79 | K31: RWD | L31: 6 | M31: 6 | N31: 679 | O31: MIDC Part 1 + Part 2 | P31: 500 | Q31: 478 | R31: 70 | S31: 6.33 | T31: Maker real-world claim (estimate) | U31: =IF(S31="","",((1-Assumptions!$B$4)*Assumptions!$B$2+Assumptions!$B$4*Assumptions!$B$3)/S31) -> 1.4849921 | V31: =IF(U31="","",U31*Assumptions!$B$5*365*Assumptions!$B$6) -> 108404.42 | W31: No | X31: 60000 | Y31: 7.2 kW wall box ₹60,000 (Mahindra XEV 9e/9S pages) | Z31: =IF(OR(G31<>"battery included",H31="",V31=""),"",H31+X31+V31) -> 3183404.4 | AA31: 527 | AB31: 205 | AC31: 222 | AD31: 7 | AE31: Yes | AF31: L2+ | AG31: 360° | AH31: Openable panoramic | AI31: Yes | AJ31: Yes | AK31: 180 | AL31: 142.2 | AM31: =IF(OR(S31="",AL31=""),"",100/S31/AL31*60) -> 6.6657335 | AN31: 11.7 | AO31: 11 | AP31: Lifetime (1st owner) | AQ31: Not tested | AV31: No Bharat NCAP crash test; Wall charger not in price (~₹60,000)
A32: MAHINDRA-XEV9S-PACKONEABOVE-59-BAAS | B32: V034 | C32: Mahindra | D32: XEV 9S | E32: SUV | F32: Pack One Above 59 kWh BaaS | G32: BaaS | H32: 1265000 | I32: verified | J32: 59 | K32: RWD | L32: 7 | M32: 7 | N32: 521 | O32: MIDC Part 1 + Part 2 | P32: 400 | S32: 6.78 | T32: Maker real-world claim (estimate) | U32: =IF(S32="","",((1-Assumptions!$B$4)*Assumptions!$B$2+Assumptions!$B$4*Assumptions!$B$3)/S32) -> 1.3864307 | V32: =IF(U32="","",U32*Assumptions!$B$5*365*Assumptions!$B$6) -> 101209.44 | W32: No | X32: 60000 | Y32: 7.2 kW wall box ₹60,000 (Mahindra XEV 9e/9S pages) | Z32: =IF(OR(G32<>"battery included",H32="",V32=""),"",H32+X32+V32) | AA32: 527 | AB32: 205 | AC32: 222 | AD32: 6 | AE32: Yes | AF32: None | AG32: Rear camera | AH32: Openable panoramic | AI32: No | AJ32: No | AK32: 140 | AL32: 106.2 | AM32: =IF(OR(S32="",AL32=""),"",100/S32/AL32*60) -> 8.3329167 | AN32: 8.7 | AO32: 11 | AP32: Lifetime (1st owner) | AQ32: Not tested | AV32: No Bharat NCAP crash test; BaaS: battery paid via separate loan (up to 8 yrs); not pay-per-km
A33: MAHINDRA-XEV9S-PACKONEABOVE-79-BAAS | B33: V036 | C33: Mahindra | D33: XEV 9S | E33: SUV | F33: Pack One Above 79 kWh BaaS | G33: BaaS | H33: 1265000 | I33: verified | J33: 79 | K33: RWD | L33: 7 | M33: 7 | N33: 679 | O33: MIDC Part 1 + Part 2 | P33: 500 | Q33: 478 | R33: 70 | S33: 6.33 | T33: Maker real-world claim (estimate) | U33: =IF(S33="","",((1-Assumptions!$B$4)*Assumptions!$B$2+Assumptions!$B$4*Assumptions!$B$3)/S33) -> 1.4849921 | V33: =IF(U33="","",U33*Assumptions!$B$5*365*Assumptions!$B$6) -> 108404.42 | W33: No | X33: 60000 | Y33: 7.2 kW wall box ₹60,000 (Mahindra XEV 9e/9S pages) | Z33: =IF(OR(G33<>"battery included",H33="",V33=""),"",H33+X33+V33) | AA33: 527 | AB33: 205 | AC33: 222 | AD33: 6 | AE33: Yes | AF33: None | AG33: Rear camera | AH33: Openable panoramic | AI33: No | AJ33: No | AK33: 180 | AL33: 142.2 | AM33: =IF(OR(S33="",AL33=""),"",100/S33/AL33*60) -> 6.6657335 | AN33: 11.7 | AO33: 11 | AP33: Lifetime (1st owner) | AQ33: Not tested | AV33: No Bharat NCAP crash test; BaaS: battery paid via separate loan (up to 8 yrs); not pay-per-km
A34: MAHINDRA-XEV9S-PACKTWOABOVE-79-BAAS | B34: V040 | C34: Mahindra | D34: XEV 9S | E34: SUV | F34: Pack Two Above 79 kWh BaaS | G34: BaaS | H34: 1595000 | I34: verified | J34: 79 | K34: RWD | L34: 7 | M34: 6 or 7 | N34: 679 | O34: MIDC Part 1 + Part 2 | P34: 500 | Q34: 478 | R34: 70 | S34: 6.33 | T34: Maker real-world claim (estimate) | U34: =IF(S34="","",((1-Assumptions!$B$4)*Assumptions!$B$2+Assumptions!$B$4*Assumptions!$B$3)/S34) -> 1.4849921 | V34: =IF(U34="","",U34*Assumptions!$B$5*365*Assumptions!$B$6) -> 108404.42 | W34: No | X34: 60000 | Y34: 7.2 kW wall box ₹60,000 (Mahindra XEV 9e/9S pages) | Z34: =IF(OR(G34<>"battery included",H34="",V34=""),"",H34+X34+V34) | AA34: 527 | AB34: 205 | AC34: 222 | AD34: 6 | AE34: Yes | AF34: L2 | AG34: 360° | AH34: Openable panoramic | AI34: Yes | AJ34: No | AK34: 180 | AL34: 142.2 | AM34: =IF(OR(S34="",AL34=""),"",100/S34/AL34*60) -> 6.6657335 | AN34: 11.7 | AO34: 11 | AP34: Lifetime (1st owner) | AQ34: Not tested | AV34: No Bharat NCAP crash test; BaaS: battery paid via separate loan (up to 8 yrs); not pay-per-km
A35: MAHINDRA-XEV9S-PACKTWOABOVE-70-BAAS | B35: V038 | C35: Mahindra | D35: XEV 9S | E35: SUV | F35: Pack Two Above 70 kWh BaaS | G35: BaaS | H35: 1605000 | I35: verified | J35: 70 | K35: RWD | L35: 7 | M35: 6 or 7 | N35: 600 | O35: MIDC Part 1 + Part 2 | P35: 450 | S35: 6.43 | T35: Maker real-world claim (estimate) | U35: =IF(S35="","",((1-Assumptions!$B$4)*Assumptions!$B$2+Assumptions!$B$4*Assumptions!$B$3)/S35) -> 1.4618974 | V35: =IF(U35="","",U35*Assumptions!$B$5*365*Assumptions!$B$6) -> 106718.51 | W35: No | X35: 60000 | Y35: 7.2 kW wall box ₹60,000 (Mahindra XEV 9e/9S pages) | Z35: =IF(OR(G35<>"battery included",H35="",V35=""),"",H35+X35+V35) | AA35: 527 | AB35: 205 | AC35: 222 | AD35: 6 | AE35: Yes | AF35: L2 | AG35: 360° | AH35: Openable panoramic | AI35: Yes | AJ35: No | AK35: 160 | AL35: 126 | AM35: =IF(OR(S35="",AL35=""),"",100/S35/AL35*60) -> 7.4057617 | AN35: 10.2 | AO35: 11 | AP35: Lifetime (1st owner) | AQ35: Not tested | AV35: No Bharat NCAP crash test; BaaS: battery paid via separate loan (up to 8 yrs); not pay-per-km
A36: MAHINDRA-XEV9S-PACKTHREE-79-BAAS | B36: V042 | C36: Mahindra | D36: XEV 9S | E36: SUV | F36: Pack Three 79 kWh BaaS | G36: BaaS | H36: 1785000 | I36: verified | J36: 79 | K36: RWD | L36: 7 | M36: 6 or 7 | N36: 679 | O36: MIDC Part 1 + Part 2 | P36: 500 | Q36: 478 | R36: 70 | S36: 6.33 | T36: Maker real-world claim (estimate) | U36: =IF(S36="","",((1-Assumptions!$B$4)*Assumptions!$B$2+Assumptions!$B$4*Assumptions!$B$3)/S36) -> 1.4849921 | V36: =IF(U36="","",U36*Assumptions!$B$5*365*Assumptions!$B$6) -> 108404.42 | W36: No | X36: 60000 | Y36: 7.2 kW wall box ₹60,000 (Mahindra XEV 9e/9S pages) | Z36: =IF(OR(G36<>"battery included",H36="",V36=""),"",H36+X36+V36) | AA36: 527 | AB36: 205 | AC36: 222 | AD36: 7 | AE36: Yes | AF36: L2+ | AG36: 360° | AH36: Openable panoramic | AI36: Yes | AJ36: Yes | AK36: 180 | AL36: 142.2 | AM36: =IF(OR(S36="",AL36=""),"",100/S36/AL36*60) -> 6.6657335 | AN36: 11.7 | AO36: 11 | AP36: Lifetime (1st owner) | AQ36: Not tested | AV36: No Bharat NCAP crash test; BaaS: battery paid via separate loan (up to 8 yrs); not pay-per-km
A37: MAHINDRA-XEV9S-PACKTHREEABOVE-79-BAAS | B37: V044 | C37: Mahindra | D37: XEV 9S | E37: SUV | F37: Pack Three Above 79 kWh BaaS | G37: BaaS | H37: 1995000 | I37: verified | J37: 79 | K37: RWD | L37: 7 | M37: 6 or 7 | N37: 679 | O37: MIDC Part 1 + Part 2 | P37: 500 | Q37: 478 | R37: 70 | S37: 6.33 | T37: Maker real-world claim (estimate) | U37: =IF(S37="","",((1-Assumptions!$B$4)*Assumptions!$B$2+Assumptions!$B$4*Assumptions!$B$3)/S37) -> 1.4849921 | V37: =IF(U37="","",U37*Assumptions!$B$5*365*Assumptions!$B$6) -> 108404.42 | W37: No | X37: 60000 | Y37: 7.2 kW wall box ₹60,000 (Mahindra XEV 9e/9S pages) | Z37: =IF(OR(G37<>"battery included",H37="",V37=""),"",H37+X37+V37) | AA37: 527 | AB37: 205 | AC37: 222 | AD37: 7 | AE37: Yes | AF37: L2+ | AG37: 360° | AH37: Openable panoramic | AI37: Yes | AJ37: Yes | AK37: 180 | AL37: 142.2 | AM37: =IF(OR(S37="",AL37=""),"",100/S37/AL37*60) -> 6.6657335 | AN37: 11.7 | AO37: 11 | AP37: Lifetime (1st owner) | AQ37: Not tested | AV37: No Bharat NCAP crash test; BaaS: battery paid via separate loan (up to 8 yrs); not pay-per-km
A38: MAHINDRA-XEV9E-PACKONE-59 | B38: V021 | C38: Mahindra | D38: XEV 9e | E38: SUV coupé | F38: Pack One 59 kWh | G38: battery included | H38: 2190000 | I38: verified | J38: 59 | K38: RWD | L38: 5 | M38: 5 | N38: 522 | O38: MIDC Part 1 + Part 2 | P38: 400 | S38: 6.78 | T38: Maker real-world claim (estimate) | U38: =IF(S38="","",((1-Assumptions!$B$4)*Assumptions!$B$2+Assumptions!$B$4*Assumptions!$B$3)/S38) -> 1.3864307 | V38: =IF(U38="","",U38*Assumptions!$B$5*365*Assumptions!$B$6) -> 101209.44 | W38: No | X38: 60000 | Y38: 7.2 kW wall box ₹60,000 (Mahindra XEV 9e/9S pages) | Z38: =IF(OR(G38<>"battery included",H38="",V38=""),"",H38+X38+V38) -> 2351209.4 | AA38: 663 | AB38: 207 | AC38: 218 | AD38: 6 | AE38: Yes | AF38: None | AG38: Rear camera | AH38: Not stated | AI38: No | AJ38: No | AK38: 140 | AL38: 106.2 | AM38: =IF(OR(S38="",AL38=""),"",100/S38/AL38*60) -> 8.3329167 | AN38: 8.7 | AO38: 11 | AP38: Lifetime (1st owner) | AQ38: Rated, applies | AR38: 32 | AS38: 45 | AV38: Wall charger not in price (~₹60,000)
A39: MAHINDRA-XEV9E-PACKTWO-59 | B39: V023 | C39: Mahindra | D39: XEV 9e | E39: SUV coupé | F39: Pack Two 59 kWh | G39: battery included | H39: 2490000 | I39: verified | J39: 59 | K39: RWD | L39: 5 | M39: 5 | N39: 522 | O39: MIDC Part 1 + Part 2 | P39: 400 | S39: 6.78 | T39: Maker real-world claim (estimate) | U39: =IF(S39="","",((1-Assumptions!$B$4)*Assumptions!$B$2+Assumptions!$B$4*Assumptions!$B$3)/S39) -> 1.3864307 | V39: =IF(U39="","",U39*Assumptions!$B$5*365*Assumptions!$B$6) -> 101209.44 | W39: No | X39: 60000 | Y39: 7.2 kW wall box ₹60,000 (Mahindra XEV 9e/9S pages) | Z39: =IF(OR(G39<>"battery included",H39="",V39=""),"",H39+X39+V39) -> 2651209.4 | AA39: 663 | AB39: 207 | AC39: 218 | AD39: 6 | AE39: Yes | AF39: L2 | AG39: Rear camera | AH39: Not stated | AI39: No | AJ39: No | AK39: 140 | AL39: 106.2 | AM39: =IF(OR(S39="",AL39=""),"",100/S39/AL39*60) -> 8.3329167 | AN39: 8.7 | AO39: 11 | AP39: Lifetime (1st owner) | AQ39: Rated, applies | AR39: 32 | AS39: 45 | AV39: Wall charger not in price (~₹60,000)
A40: MAHINDRA-XEV9E-PACKTWO-79 | B40: V025 | C40: Mahindra | D40: XEV 9e | E40: SUV coupé | F40: Pack Two 79 kWh | G40: battery included | H40: 2650000 | I40: corroborated | J40: 79 | K40: RWD | L40: 5 | M40: 5 | N40: 656 | O40: MIDC Part 1 + Part 2 | P40: 500 | Q40: 456 | R40: 70 | S40: 6.33 | T40: Maker real-world claim (estimate) | U40: =IF(S40="","",((1-Assumptions!$B$4)*Assumptions!$B$2+Assumptions!$B$4*Assumptions!$B$3)/S40) -> 1.4849921 | V40: =IF(U40="","",U40*Assumptions!$B$5*365*Assumptions!$B$6) -> 108404.42 | W40: No | X40: 60000 | Y40: 7.2 kW wall box ₹60,000 (Mahindra XEV 9e/9S pages) | Z40: =IF(OR(G40<>"battery included",H40="",V40=""),"",H40+X40+V40) -> 2818404.4 | AA40: 663 | AB40: 207 | AC40: 218 | AD40: 6 | AE40: Yes | AF40: L2 | AG40: Rear camera | AH40: Not stated | AI40: No | AJ40: No | AK40: 180 | AL40: 142.2 | AM40: =IF(OR(S40="",AL40=""),"",100/S40/AL40*60) -> 6.6657335 | AN40: 11.7 | AO40: 11 | AP40: Lifetime (1st owner) | AQ40: Rated, applies | AR40: 32 | AS40: 45 | AV40: Wall charger not in price (~₹60,000); Price corroborated, confirm before buying
...

Sheet Variant_Ladder
A1: model | B1: from_variant | C1: to_variant | D1: from_price_inr | E1: to_price_inr | F1: extra_cost_inr | G1: what_you_gain | H1: what_does_not_change | I1: factory_only_gains | J1: note
A2: BE 6 SPORTEQ | B2: One 59 kWh | C2: Two 59 kWh | D2: 1945000 | E2: 2095000 | F2: =E2-D2 -> 150000 | G2: Camera: Rear camera → 540°; Audio: 6 speakers → 16-speaker Harman Kardon, Dolby Atmos; Screens: Dual 31.24 cm → Triple 31.24 cm; Wheels: R18 steel, aero covers → R19 Versa steel, aero covers; Climate: Single zone auto, rear AC vents → Dual zone auto, rear AC vents | I2: None (accessories may cover some)
A3: BE 6 SPORTEQ | B3: Two 59 kWh | C3: Three 59 kWh | D3: 2095000 | E3: 2195000 | F3: =E3-D3 -> 100000 | G3: Sunroof: None → Panoramic; Vent. seats: No → Yes; Wheels: R19 Versa steel, aero covers → R19 alloy; Powered seat: no → yes (6-way) | I3: Sunroof, Vent. seats
A4: BE 6 SPORTEQ | B4: Three 59 kWh | C4: Three 70 kWh | D4: 2195000 | E4: 2295000 | F4: =E4-D4 -> 100000 | G4: Battery kWh: 59 → 70; Range km: 573 → 651 | I4: Battery kWh, Range km
A5: BE 6 SPORTEQ | B5: Three 70 kWh | C5: Three+ 70 kWh | D5: 2295000 | E5: 2395000 | F5: =E5-D5 -> 100000 | G5: ADAS: None → L2; Power tailgate: no → yes (gesture) | I5: ADAS
A6: BE 6 SPORTEQ | B6: Three+ 70 kWh | C6: FE 79 kWh | D6: 2395000 | E6: 2445000 | F6: =E6-D6 -> 50000 | G6: Battery kWh: 70 → 79; Range km: 651 → 708; ADAS: L2 → None; Vent. seats: Yes → No; Screens: Triple 31.24 cm → Dual 31.24 cm; Wheels: R19 alloy → R20 alloy; Power tailgate: yes (gesture) → no; Powered seat: yes (6-way) → no; Adaptive suspension: no → yes | I6: ADAS, Adaptive suspension, Battery kWh, Range km, Vent. seats
A7: BE 6 SPORTEQ | B7: FE 79 kWh | C7: Three+ 79 kWh | D7: 2445000 | E7: 2495000 | F7: =E7-D7 -> 50000 | G7: ADAS: None → L2; Vent. seats: No → Yes; Screens: Dual 31.24 cm → Triple 31.24 cm; Wheels: R20 alloy → R19 alloy; Power tailgate: no → yes (gesture); Powered seat: no → yes (6-way); Adaptive suspension: yes → no | I7: ADAS, Adaptive suspension, Vent. seats
A8: BE 6 SPORTEQ | B8: Three+ 79 kWh | C8: Four 79 kWh | D8: 2495000 | E8: 2695000 | F8: =E8-D8 -> 200000 | G8: ADAS: L2 → L2+; HUD: no → yes (AR HUD); Auto park: no → yes; Adaptive suspension: no → yes | I8: ADAS, Adaptive suspension, HUD
A9: BE 6 SPORTEQ | B9: Four 79 kWh | C9: FE Four 79 kWh | D9: 2695000 | E9: 2695000 | F9: =E9-D9 -> 0 | G9: Vent. seats: Yes → Not stated; Screens: Triple 31.24 cm → Dual 31.24 cm; Wheels: R19 alloy → R20 alloy; Powered seat: yes (6-way) → CHECK | I9: Vent. seats | J9: Same price
A10: BE 6 SPORTEQ | B10: FE Four 79 kWh | C10: Launch Edition 79 kWh | D10: 2695000 | E10: 2695000 | F10: =E10-D10 -> 0 | G10: Vent. seats: Not stated → Yes; Screens: Dual 31.24 cm → Triple 31.24 cm; Wheels: R20 alloy → R19 alloy; Powered seat: CHECK → yes (6-way) | I10: Vent. seats | J10: Same price
A11: Curvv.ev | B11: Accomplished X 55 | C11: Empowered X 55 | D11: 1719000 | E11: 1939000 | F11: =E11-D11 -> 220000 | G11: ADAS: None → L2; Vent. seats: Passive only → Yes; Charger in box: Unclear → Yes (7.2 kW); Audio: 4 speakers + 4 tweeters → JBL 9 speakers with subwoofer; Screens: 26.03 cm touchscreen + 26.03 cm cockpit → 31.24 cm touchscreen; Power tailgate: no → yes (gesture); Powered seat: — → 6-way powered; App suite: Not listed → Arcade.ev | I11: ADAS, Vent. seats
A12: Harrier.ev | B12: Adventure 65 | C12: Adventure S 65 | D12: 2179000 | E12: 2229000 | F12: =E12-D12 -> 50000 | G12: Sunroof: None → Panoramic; Screens: 26.03 cm touchscreen + 26.03 cm cockpit → 31.24 cm touchscreen + 26.03 cm cockpit; App suite: no → Arcade.ev | I12: Sunroof
A13: Harrier.ev | B13: Adventure S 65 | C13: Fearless+ 65 | D13: 2229000 | E13: 2429000 | F13: =E13-D13 -> 200000 | G13: Airbags: 6 → 7; Camera: Not stated → 360°; Vent. seats: No → Yes; Audio: Not listed → JBL Black 10 speakers incl. subwoofer; Climate: Single zone FATC → Dual zone FATC, voice assisted; Powered seat: no (8-way manual driver) → yes (6-way powered, memory, welcome retract); Wireless charger: — → yes | I13: Airbags, Vent. seats
A14: Harrier.ev | B14: Fearless+ 65 | C14: Fearless+ 75 | D14: 2429000 | E14: 2529000 | F14: =E14-D14 -> 100000 | G14: Battery kWh: 65 → 75; Range km: 538 → 627 | I14: Battery kWh, Range km
A15: Harrier.ev | B15: Fearless+ 75 | C15: Fearless+ QWD 75 (AWD) | D15: 2529000 | E15: 2679000 | F15: =E15-D15 -> 150000 | G15: Range km: 627 → 622; Drive: RWD → AWD; Terrain modes: 3 → 6 | I15: Drive, Range km, Terrain modes
A16: Harrier.ev | B16: Fearless+ QWD 75 (AWD) | C16: Empowered 75 | D16: 2679000 | E16: 2779000 | F16: =E16-D16 -> 100000 | G16: Range km: 622 → 627; Drive: AWD → RWD; ADAS: None → L2; Camera: 360° → 540°; Terrain modes: 6 → 4; Audio: JBL Black 10 speakers incl. subwoofer → JBL Black 10 speakers, Dolby Atmos; Screens: 31.24 cm touchscreen + 26.03 cm cockpit → 36.9 cm (14.53 in) Samsung Neo QLED touchscreen; Auto park: no → yes (15 features incl. Summon, Anywhere Parking); Power tailgate: no → yes (gesture) | I16: ADAS, Drive, Range km, Terrain modes
A17: Harrier.ev | B17: Empowered 75 | C17: Empowered QWD 75 (AWD) | D17: 2779000 | E17: 2929000 | F17: =E17-D17 -> 150000 | G17: Range km: 627 → 622; Drive: RWD → AWD; Terrain modes: 4 → 6 | I17: Drive, Range km, Terrain modes
A18: Nexon.ev | B18: Creative+ MR | C18: Fearless MR | D18: 1249000 | E18: 1329000 | F18: =E18-D18 -> 80000 | G18: Audio: 4 speakers → 4 speakers + 4 tweeters; Screens: 17.78 cm touchscreen → 26.03 cm touchscreen + 26.03 cm cockpit | I18: None (accessories may cover some)
A19: Nexon.ev | B19: Fearless MR | C19: Creative 45 | D19: 1329000 | E19: 1434000 | F19: =E19-D19 -> 105000 | G19: Battery kWh: 30 → 45; Range km: 275 → 489; Battery warranty: 8 yrs / 1.6L km → Lifetime (1st owner); Crash test: Rated, coverage unconfirmed → Rated, applies; Audio: 4 speakers + 4 tweeters → 4 speakers; Screens: 26.03 cm touchscreen + 26.03 cm cockpit → 17.78 cm touchscreen; Keyless: — → yes (PEPS) | I19: Battery kWh, Battery warranty, Range km
A20: Nexon.ev | B20: Creative 45 | C20: Fearless 45 | D20: 1434000 | E20: 1534000 | F20: =E20-D20 -> 100000 | G20: Audio: 4 speakers → 4 speakers + 4 tweeters; Screens: 17.78 cm touchscreen → 26.03 cm touchscreen + 26.03 cm cockpit | I20: None (accessories may cover some)
A21: Nexon.ev | B21: Fearless 45 | C21: Empowered 45 | D21: 1534000 | E21: 1634000 | F21: =E21-D21 -> 100000 | G21: Camera: Rear camera → 360°; Sunroof: None → Sunroof; Audio: 4 speakers + 4 tweeters → JBL audio modes; Upholstery: — → Leatherette; Cruise: — → Standard; Wireless charger: — → yes | I21: Sunroof
A22: Nexon.ev | B22: Empowered 45 | C22: Empowered+A 45 | D22: 1634000 | E22: 1769000 | F22: =E22-D22 -> 135000 | G22: ADAS: None → L2; Sunroof: Sunroof → Panoramic; Vent. seats: No → Yes; Charger in box: Not stated → Yes (7.2 kW); Audio: JBL audio modes → JBL 9-speaker with subwoofer; Screens: 26.03 cm touchscreen + 26.03 cm cockpit → 31.24 cm touchscreen + 26.03 cm cockpit; App suite: no → Arcade.ev | I22: ADAS, Sunroof, Vent. seats
... A42: XEV 9S | B42: Pack One Above 79 kWh | C42: Pack Two Above 70 kWh (7-seater) | D42: 2265000 | E42: 2505000 | F42: =E42-D42 -> 240000 | G42: Battery kWh: 79 → 70; Range km: 679 → 600; ADAS: None → L2; Camera: Rear camera → 360°; Vent. seats: No → Yes; Audio: 6 speakers → 16-speaker Harman Kardon, Dolby Atmos; Wheels: R18 stylised wheel → R18 alloy; Upholstery: Premium fabric → Leatherette; Climate: Single zone auto, rear AC vents → Dual zone auto, rear AC vents; Powered seat: no (6-way manual) → yes (6-way powered, memory); Cruise: Standard → Adaptive; Wireless charger: None → Front | I42: ADAS, Battery kWh, Range km, Vent. seats
A43: XEV 9S | B43: Pack Two Above 70 kWh (7-seater) | C43: Pack Two Above 70 kWh (6-seater) | D43: 2505000 | E43: 2525000 | F43: =E43-D43 -> 20000 | G43: Seats: 7 → 6 | I43: Seats | J43: Captain-seat version
A44: XEV 9S | B44: Pack Two Above 70 kWh (6-seater) | C44: Pack Two Above 79 kWh (7-seater) | D44: 2525000 | E44: 2595000 | F44: =E44-D44 -> 70000 | G44: Battery kWh: 70 → 79; Range km: 600 → 679; Seats: 6 → 7 | I44: Battery kWh, Range km, Seats
A45: XEV 9S | B45: Pack Two Above 79 kWh (7-seater) | C45: Pack Two Above 79 kWh (6-seater) | D45: 2595000 | E45: 2615000 | F45: =E45-D45 -> 20000 | G45: Seats: 7 → 6 | I45: Seats | J45: Captain-seat version
A46: XEV 9S | B46: Pack Two Above 79 kWh (6-seater) | C46: Pack Three 79 kWh (7-seater) | D46: 2615000 | E46: 2785000 | F46: =E46-D46 -> 170000 | G46: Seats: 6 → 7; Airbags: 6 → 7; ADAS: L2 → L2+; Keyless: no → yes; Wireless charger: Front → Front & rear; Adaptive suspension: no → yes | I46: ADAS, Adaptive suspension, Airbags, Seats
A47: XEV 9S | B47: Pack Three 79 kWh (7-seater) | C47: Pack Three 79 kWh (6-seater) | D47: 2785000 | E47: 2805000 | F47: =E47-D47 -> 20000 | G47: Seats: 7 → 6 | I47: Seats | J47: Captain-seat version
A48: XEV 9S | B48: Pack Three 79 kWh (6-seater) | C48: Pack Three Above 79 kWh (7-seater) | D48: 2805000 | E48: 2995000 | F48: =E48-D48 -> 190000 | G48: Seats: 6 → 7; HUD: no → yes (AR HUD); Auto park: no → yes | I48: HUD, Seats
A49: XEV 9S | B49: Pack Three Above 79 kWh (7-seater) | C49: Pack Three Above 79 kWh (6-seater) | D49: 2995000 | E49: 3015000 | F49: =E49-D49 -> 20000 | G49: Seats: 7 → 6 | I49: Seats | J49: Captain-seat version
A50: XEV 9e | B50: Pack One 59 kWh | C50: Pack Two 59 kWh | D50: 2190000 | E50: 2490000 | F50: =E50-D50 -> 300000 | G50: ADAS: None → L2; Audio: 6 speakers → 16-speaker Harman Kardon, Dolby Atmos; Wheels: R19 stylised wheel → R19 alloy; Upholstery: Premium fabric → Leatherette; Climate: Single zone auto, rear AC vents → Dual zone auto, rear AC vents; Powered seat: no (6-way manual) → yes (6-way powered, memory); Cruise: Standard → Adaptive; Wireless charger: None → Front | I50: ADAS
A51: XEV 9e | B51: Pack Two 59 kWh | C51: Pack Two 79 kWh | D51: 2490000 | E51: 2650000 | F51: =E51-D51 -> 160000 | G51: Battery kWh: 59 → 79; Range km: 522 → 656 | I51: Battery kWh, Range km
A52: XEV 9e | B52: Pack Two 79 kWh | C52: Pack Three Select 59 kWh | D52: 2650000 | E52: 2790000 | F52: =E52-D52 -> 140000 | G52: Battery kWh: 79 → 59; Range km: 656 → 522; Airbags: 6 → 7; Camera: Rear camera → 360°; Vent. seats: No → Yes; Auto park: no → yes; Power tailgate: no → yes (gesture); Keyless: no → yes; Wireless charger: Front → Front & rear; Adaptive suspension: no → yes | I52: Adaptive suspension, Airbags, Battery kWh, Range km, Vent. seats
A53: XEV 9e | B53: Pack Three Select 59 kWh | C53: Cineluxe 79 kWh | D53: 2790000 | E53: 2935000 | F53: =E53-D53 -> 145000 | G53: Battery kWh: 59 → 79; Range km: 522 → 656; Airbags: 7 → None; ESP: Yes → Not stated; ADAS: L2 → Not stated; Camera: 360° → Not stated; Vent. seats: Yes → Not stated; Screens: — → Coast-to-coast HD screens; Wheels: R19 alloy → R19; Upholstery: Leatherette → Distinct leatherette (Cineluxe-specific); App suite: Fun&Work (60+ in-built apps) → Not stated for Cineluxe | I53: ADAS, Airbags, Battery kWh, ESP, Range km, Vent. seats
A54: XEV 9e | B54: Cineluxe 79 kWh | C54: Pack Three 79 kWh | D54: 2935000 | E54: 3050000 | F54: =E54-D54 -> 115000 | G54: Airbags: None → 7; ESP: Not stated → Yes; ADAS: Not stated → L2+; Camera: Not stated → 360°; Vent. seats: Not stated → Yes; Wheels: R19 → R19 alloy; HUD: — → yes (AR HUD); Auto park: — → yes; Power tailgate: — → yes (gesture); Upholstery: Distinct leatherette (Cineluxe-specific) → Leatherette; Climate: — → Dual zone auto, rear AC vents; Powered seat: — → yes (6-way powered, memory); Cruise: — → Adaptive; Keyless: — → yes; Wireless charger: — → Front & rear; App suite: Not stated for Cineluxe → Fun&Work (60+ in-built apps) | I54: ADAS, Airbags, ESP, HUD, Vent. seats
A55: XUV 3XO EV | B55: AX5 39.4 kWh | C55: AX7L 39.4 kWh | D55: 1389000 | E55: 1496000 | F55: =E55-D55 -> 107000 | G55: ADAS: None → L2; Camera: Rear camera → 360°; Sunroof: Sunroof → Panoramic; Audio: 6 speakers → 7-speaker Harman Kardon with subwoofer, Dolby Atmos; Wheels: R16 diamond-cut alloy → R17 diamond-cut alloy; Upholstery: Not leatherette (AX7L adds leatherette seats) → Leatherette | I55: ADAS, Sunroof

Sheet Test_Cases
A1: buyer_profile | B1: rank | C1: variant | D1: price_inr | E1: 5yr_cost_inr (40 km/day, ₹9.4/kWh) | F1: why_it_fits | G1: watch_outs | H1: cheaper_alternative_note
A2: First EV, city commute, tight budget | B2: 1 | C2: Tiago.ev Smart 19 | D2: 699000 | E2: 781377 | F2: Tiago.ev Hatchback, 5 seats, claimed 226 km, maker real-world 160+ km, ESP Not listed, ADAS Not stated, camera Sensors only, NCAP Not tested | G2: ESP not listed; No Bharat NCAP crash test; Battery warranty 8 yrs/1.6L km (not lifetime); Slow DC fast-charging
B3: 2 | C3: Tiago.ev Pure+ 19 | D3: 864000 | E3: 946377 | F3: Tiago.ev Hatchback, 5 seats, claimed 226 km, maker real-world 160+ km, ESP Not listed, ADAS Not stated, camera Rear camera, NCAP Not tested | G3: ESP not listed; No Bharat NCAP crash test; Battery warranty 8 yrs/1.6L km (not lifetime); Slow DC fast-charging
